Workbook
Name IQ_CH: 110000
Name IQ_CQ: 5000
Name IQ_CY: 10000
Name IQ_DAILY: 500000
Name IQ_FH: 100000
Name IQ_FQ: 500
Name IQ_FY: 1000
Name IQ_LTM: 2000
Name IQ_MONTH: 15000
Name IQ_NTM: 6000
Name IQ_WEEK: 50000
Name IQ_YTD: 3000

Sheet Cover
B2: Avoided Cost Calculator - Gas
B3: 2024 ACC Gas model v1b
B4: Prepared by:
B9: Energy and Environmental Economics, Inc.
B10: 44 Montgomery Street, Suite 1500
B11: San Francisco, CA 94104
B12: Phone: 415-391-5100
B13: 45590
B26: Cell Color Coding
B27: Input
B28: Calculated Value
B29: User Input
B30: Lookup Formula
B31: Yearly Lookup Value
B32: Final Outputs
B33: Values Pasted from Calculation/Macros

Sheet User Dashboard
B2: Main Inputs
C4: User Inputs
B5: Utility | C5: SDG&E
B6: Class | C6: Total Core
B7: End Use | C7: Small Boiler (<100MMBtu/Hr)
B8: Emission Control | C8: Uncontrolled
B10: Cost Test | C10: TRC
B11: Societal Cost of Carbon (SCC) | C11: High | D11: (SCC values are only used for the SCT)
C13: Levelized Results Settings
B14: Start year | C14: 2024
B15: Levelization Period | C15: 1 | D15: (Enter 1 yr to show single year results)
B16: Last Year | C16: =C14+C15-1 -> 2024 | E16: =IF(C16>$AJ$47,_xlfn.CONCAT("Selected Levelization Period extends beyond the modelled years (",E58,"-",$AJ$47,"). Please update the Start Year and/or Levelization Period"),"")
B17: Nominal Discount Rate | C17: =INDEX('Other Inputs'!$C$18:$D$18,MATCH($C$10,'Other Inputs'!$C$16:$D$16,0)) -> 0
B18: Annualization | C18: =-PMT(C17,C15,1,0,1) -> 1
B19: Report Results in Dollar Year | C19: 2024
B20: Inflation Rate | C20: ='Other Inputs'!$C$11 -> 0.02
C22: Components to Include
B23: Market (Commodity) | C23: TRUE
B24: T&D | C24: TRUE
B25: Environment (CO2 & NOx) | C25: TRUE
B26: Upstream methane leakage | C26: TRUE
B27: Behind-the-meter methane leakage | C27: TRUE
B28: Air Quality Adder | C28: TRUE
B29: Final Air Quality Adder | C29: =IF(AND(C10="SCT",C28),TRUE(),FALSE()) -> FALSE | D29: * Included for SCT only. Does not include NOx value, which is included in Environment component
B31: Intermediate Values
C33: Active values based on user inputs | F33: Month | G33: T&D Allocation Factor
B34: NOx (lbs/therm) | C34: =INDEX(Emissions!$F$6:$F$12,MATCH(_xlfn.CONCAT($C$7,"-",$C$8),Emissions!$H$6:$H$12,0)) -> 0.0098 | F34: January | G34: =INDEX('T&D'!$C55:$K55,MATCH(_xlfn.CONCAT($C$5,"-",$C$6),'T&D'!$C$68:$K$68,0)) -> 1.8214936
B35: CO2 (tonnes/therm) | C35: =INDEX(Emissions!$G$6:$G$12,MATCH(_xlfn.CONCAT($C$7,"-",$C$8),Emissions!$H$6:$H$12,0)) -> 0.005307037 | F35: February | G35: =INDEX('T&D'!$C56:$K56,MATCH(_xlfn.CONCAT($C$5,"-",$C$6),'T&D'!$C$68:$K$68,0)) -> 1.8214936
B36: Compression | C36: =INDEX('Other Inputs'!$C5:$E5,MATCH($C$5,'Other Inputs'!$C$4:$E$4,0)) -> 0.004 | F36: March | G36: =INDEX('T&D'!$C57:$K57,MATCH(_xlfn.CONCAT($C$5,"-",$C$6),'T&D'!$C$68:$K$68,0)) -> 1.8214936
B37: Losses and Unaccounted | C37: =INDEX('Other Inputs'!$C6:$E6,MATCH($C$5,'Other Inputs'!$C$4:$E$4,0)) -> 0.01 | F37: April | G37: =INDEX('T&D'!$C58:$K58,MATCH(_xlfn.CONCAT($C$5,"-",$C$6),'T&D'!$C$68:$K$68,0)) -> 0
F38: May | G38: =INDEX('T&D'!$C59:$K59,MATCH(_xlfn.CONCAT($C$5,"-",$C$6),'T&D'!$C$68:$K$68,0)) -> 0
F39: June | G39: =INDEX('T&D'!$C60:$K60,MATCH(_xlfn.CONCAT($C$5,"-",$C$6),'T&D'!$C$68:$K$68,0)) -> 0
F40: July | G40: =INDEX('T&D'!$C61:$K61,MATCH(_xlfn.CONCAT($C$5,"-",$C$6),'T&D'!$C$68:$K$68,0)) -> 0
F41: August | G41: =INDEX('T&D'!$C62:$K62,MATCH(_xlfn.CONCAT($C$5,"-",$C$6),'T&D'!$C$68:$K$68,0)) -> 0
F42: September | G42: =INDEX('T&D'!$C63:$K63,MATCH(_xlfn.CONCAT($C$5,"-",$C$6),'T&D'!$C$68:$K$68,0)) -> 0
F43: October | G43: =INDEX('T&D'!$C64:$K64,MATCH(_xlfn.CONCAT($C$5,"-",$C$6),'T&D'!$C$68:$K$68,0)) -> 0
F44: November | G44: =INDEX('T&D'!$C65:$K65,MATCH(_xlfn.CONCAT($C$5,"-",$C$6),'T&D'!$C$68:$K$68,0)) -> 1.8214936
F45: December | G45: =INDEX('T&D'!$C66:$K66,MATCH(_xlfn.CONCAT($C$5,"-",$C$6),'T&D'!$C$68:$K$68,0)) -> 1.8214936
C47: Annual Cost by Component ($/therm) | E47: 2023 | F47: =E47+1 -> 2024 | G47: =F47+1 -> 2025 | H47: =G47+1 -> 2026 | I47: =H47+1 -> 2027 | J47: =I47+1 -> 2028 | K47: =J47+1 -> 2029 | L47: =K47+1 -> 2030 | M47: =L47+1 -> 2031 | ... AJ47: =AI47+1 -> 2054
C48: Average T&D Cost | E48: =INDEX('T&D'!$D$5:$AJ$13,MATCH(_xlfn.CONCAT($C$5,"-",$C$6),'T&D'!$AL$5:$AL$13,0),MATCH(E$47,'T&D'!$D$4:$AJ$4,0)) -> 0.27 | F48: =INDEX('T&D'!$D$5:$AJ$13,MATCH(_xlfn.CONCAT($C$5,"-",$C$6),'T&D'!$AL$5:$AL$13,0),MATCH(F$47,'T&D'!$D$4:$AJ$4,0)) -> 0.27 | G48: =INDEX('T&D'!$D$5:$AJ$13,MATCH(_xlfn.CONCAT($C$5,"-",$C$6),'T&D'!$AL$5:$AL$13,0),MATCH(G$47,'T&D'!$D$4:$AJ$4,0)) -> 0.28094472 | H48: =INDEX('T&D'!$D$5:$AJ$13,MATCH(_xlfn.CONCAT($C$5,"-",$C$6),'T&D'!$AL$5:$AL$13,0),MATCH(H$47,'T&D'!$D$4:$AJ$4,0)) -> 0.28656361 | I48: =INDEX('T&D'!$D$5:$AJ$13,MATCH(_xlfn.CONCAT($C$5,"-",$C$6),'T&D'!$AL$5:$AL$13,0),MATCH(I$47,'T&D'!$D$4:$AJ$4,0)) -> 0.29229489 | J48: =INDEX('T&D'!$D$5:$AJ$13,MATCH(_xlfn.CONCAT($C$5,"-",$C$6),'T&D'!$AL$5:$AL$13,0),MATCH(J$47,'T&D'!$D$4:$AJ$4,0)) -> 0.29814078 | K48: =INDEX('T&D'!$D$5:$AJ$13,MATCH(_xlfn.CONCAT($C$5,"-",$C$6),'T&D'!$AL$5:$AL$13,0),MATCH(K$47,'T&D'!$D$4:$AJ$4,0)) -> 0.3041036 | L48: =INDEX('T&D'!$D$5:$AJ$13,MATCH(_xlfn.CONCAT($C$5,"-",$C$6),'T&D'!$AL$5:$AL$13,0),MATCH(L$47,'T&D'!$D$4:$AJ$4,0)) -> 0.31018567 | ... AJ48: =INDEX('T&D'!$D$5:$AJ$13,MATCH(_xlfn.CONCAT($C$5,"-",$C$6),'T&D'!$AL$5:$AL$13,0),MATCH(AJ$47,'T&D'!$D$4:$AJ$4,0)) -> 0.49891419
...

Sheet Output
B2: Output Summary
C4: User Inputs (Select on Dashboard)
B5: Utility | C5: ='User Dashboard'!C5 -> SDG&E
B6: Class | C6: ='User Dashboard'!C6 -> Total Core
B7: End Use | C7: ='User Dashboard'!C7 -> Small Boiler (<100MMBtu/Hr)
B8: Emission Control | C8: ='User Dashboard'!C8 -> Uncontrolled
C10: Levelized Results Settings (Select on Dashboard)
B11: Start year | C11: ='User Dashboard'!C14 -> 2024
B12: Levelization Period | C12: ='User Dashboard'!C15 -> 1
B13: Last Year | C13: ='User Dashboard'!C16 -> 2024
C15: Levelized Gas Avoided Costs | H15: Monthly Gas Avoided Costs
C16: Monthly | D16: Annual Average | H16: ='User Dashboard'!E58 -> 2023 | I16: ='User Dashboard'!F58 -> 2024 | J16: ='User Dashboard'!G58 -> 2025 | K16: ='User Dashboard'!H58 -> 2026 | L16: ='User Dashboard'!I58 -> 2027 | M16: ='User Dashboard'!J58 -> 2028 | N16: ='User Dashboard'!K58 -> 2029 | O16: ='User Dashboard'!L58 -> 2030 | ... AM16: ='User Dashboard'!AJ58 -> 2054
B17: January | C17: ='User Dashboard'!C59 -> 1.9215379 | D17: =AVERAGE($C$17:$C$28) -> 1.6009708 | G17: January | H17: ='User Dashboard'!E59 -> 1.9117605 | I17: ='User Dashboard'!F59 -> 1.9215379 | J17: ='User Dashboard'!G59 -> 1.9698948 | K17: ='User Dashboard'!H59 -> 2.0069576 | L17: ='User Dashboard'!I59 -> 2.0430923 | M17: ='User Dashboard'!J59 -> 2.0794509 | N17: ='User Dashboard'!K59 -> 2.1163491 | O17: ='User Dashboard'!L59 -> 2.153782 | ... AM17: ='User Dashboard'!AJ59 -> 3.25223
B18: February | C18: ='User Dashboard'!C60 -> 1.9088278 | D18: =AVERAGE($C$17:$C$28) -> 1.6009708 | G18: February | H18: ='User Dashboard'!E60 -> 1.8975096 | I18: ='User Dashboard'!F60 -> 1.9088278 | J18: ='User Dashboard'!G60 -> 1.9567109 | K18: ='User Dashboard'!H60 -> 1.9934321 | L18: ='User Dashboard'!I60 -> 2.0292814 | M18: ='User Dashboard'!J60 -> 2.0653758 | N18: ='User Dashboard'!K60 -> 2.101996 | O18: ='User Dashboard'!L60 -> 2.1391295 | ... AM18: ='User Dashboard'!AJ60 -> 3.2279463
B19: March | C19: ='User Dashboard'!C61 -> 1.8618901 | D19: =AVERAGE($C$17:$C$28) -> 1.6009708 | G19: March | H19: ='User Dashboard'!E61 -> 1.849169 | I19: ='User Dashboard'!F61 -> 1.8618901 | J19: ='User Dashboard'!G61 -> 1.908433 | K19: ='User Dashboard'!H61 -> 1.9440146 | L19: ='User Dashboard'!I61 -> 1.9788417 | M19: ='User Dashboard'!J61 -> 2.0139307 | N19: ='User Dashboard'!K61 -> 2.0495141 | O19: ='User Dashboard'!L61 -> 2.0855733 | ... AM19: ='User Dashboard'!AJ61 -> 3.1390721
B20: April | C20: ='User Dashboard'!C62 -> 1.3543724 | D20: =AVERAGE($C$17:$C$28) -> 1.6009708 | G20: April | H20: ='User Dashboard'!E62 -> 1.340316 | I20: ='User Dashboard'!F62 -> 1.3543724 | J20: ='User Dashboard'!G62 -> 1.3803461 | K20: ='User Dashboard'!H62 -> 1.4053048 | L20: ='User Dashboard'!I62 -> 1.429346 | M20: ='User Dashboard'!J62 -> 1.453456 | N20: ='User Dashboard'!K62 -> 1.4778337 | O20: ='User Dashboard'!L62 -> 1.5024494 | ... AM20: ='User Dashboard'!AJ62 -> 2.2006619
B21: May | C21: ='User Dashboard'!C63 -> 1.3725626 | D21: =AVERAGE($C$17:$C$28) -> 1.6009708 | G21: May | H21: ='User Dashboard'!E63 -> 1.3570207 | I21: ='User Dashboard'!F63 -> 1.3725626 | J21: ='User Dashboard'!G63 -> 1.3988619 | K21: ='User Dashboard'!H63 -> 1.4242045 | L21: ='User Dashboard'!I63 -> 1.4486269 | M21: ='User Dashboard'!J63 -> 1.4731406 | N21: ='User Dashboard'!K63 -> 1.497925 | O21: ='User Dashboard'!L63 -> 1.5229422 | ... AM21: ='User Dashboard'!AJ63 -> 2.2347236
B22: June | C22: ='User Dashboard'!C64 -> 1.3865864 | D22: =AVERAGE($C$17:$C$28) -> 1.6009708 | G22: June | H22: ='User Dashboard'!E64 -> 1.3695061 | I22: ='User Dashboard'!F64 -> 1.3865864 | J22: ='User Dashboard'!G64 -> 1.4130993 | K22: ='User Dashboard'!H64 -> 1.4387266 | L22: ='User Dashboard'!I64 -> 1.4634401 | M22: ='User Dashboard'!J64 -> 1.4882677 | N22: ='User Dashboard'!K64 -> 1.5133667 | O22: ='User Dashboard'!L64 -> 1.5386904 | ... AM22: ='User Dashboard'!AJ64 -> 2.2609102
B23: July | C23: ='User Dashboard'!C65 -> 1.3911074 | D23: =AVERAGE($C$17:$C$28) -> 1.6009708 | G23: July | H23: ='User Dashboard'!E65 -> 1.3725349 | I23: ='User Dashboard'!F65 -> 1.3911074 | J23: ='User Dashboard'!G65 -> 1.4175939 | K23: ='User Dashboard'!H65 -> 1.4432847 | L23: ='User Dashboard'!I65 -> 1.4680847 | M23: ='User Dashboard'!J65 -> 1.4930203 | N23: ='User Dashboard'!K65 -> 1.5182232 | O23: ='User Dashboard'!L65 -> 1.5436385 | ... AM23: ='User Dashboard'!AJ65 -> 2.2691653
B24: August | C24: ='User Dashboard'!C66 -> 1.3869705 | D24: =AVERAGE($C$17:$C$28) -> 1.6009708 | G24: August | H24: ='User Dashboard'!E66 -> 1.3670138 | I24: ='User Dashboard'!F66 -> 1.3869705 | J24: ='User Dashboard'!G66 -> 1.4132186 | K24: ='User Dashboard'!H66 -> 1.4387731 | L24: ='User Dashboard'!I66 -> 1.4634737 | M24: ='User Dashboard'!J66 -> 1.4883294 | N24: ='User Dashboard'!K66 -> 1.513444 | O24: ='User Dashboard'!L66 -> 1.5387553 | ... AM24: ='User Dashboard'!AJ66 -> 2.261096
B25: September | C25: ='User Dashboard'!C67 -> 1.3948746 | D25: =AVERAGE($C$17:$C$28) -> 1.6009708 | G25: September | H25: ='User Dashboard'!E67 -> 1.3733425 | I25: ='User Dashboard'!F67 -> 1.3948746 | J25: ='User Dashboard'!G67 -> 1.4211755 | K25: ='User Dashboard'!H67 -> 1.4468703 | L25: ='User Dashboard'!I67 -> 1.4717297 | M25: ='User Dashboard'!J67 -> 1.4967672 | N25: ='User Dashboard'!K67 -> 1.5220608 | O25: ='User Dashboard'!L67 -> 1.5475398 | ... AM25: ='User Dashboard'!AJ67 -> 2.2757224
B26: October | C26: ='User Dashboard'!C68 -> 1.3918063 | D26: =AVERAGE($C$17:$C$28) -> 1.6009708 | G26: October | H26: ='User Dashboard'!E68 -> 1.3688814 | I26: ='User Dashboard'!F68 -> 1.3918063 | J26: ='User Dashboard'!G68 -> 1.4178953 | K26: ='User Dashboard'!H68 -> 1.4434786 | L26: ='User Dashboard'!I68 -> 1.4682616 | M26: ='User Dashboard'!J68 -> 1.4932424 | N26: ='User Dashboard'!K68 -> 1.5184714 | O26: ='User Dashboard'!L68 -> 1.5438706 | ... AM26: ='User Dashboard'!AJ68 -> 2.2696689
B27: November | C27: ='User Dashboard'!C69 -> 1.9181295 | D27: =AVERAGE($C$17:$C$28) -> 1.6009708 | G27: November | H27: ='User Dashboard'!E69 -> 1.8931247 | I27: ='User Dashboard'!F69 -> 1.9181295 | J27: ='User Dashboard'!G69 -> 1.9649449 | K27: ='User Dashboard'!H69 -> 2.0014945 | L27: ='User Dashboard'!I69 -> 2.0374436 | M27: ='User Dashboard'!J69 -> 2.0738338 | N27: ='User Dashboard'!K69 -> 2.1106936 | O27: ='User Dashboard'!L69 -> 2.1479375 | ... AM27: ='User Dashboard'!AJ69 -> 3.2429407
B28: December | C28: ='User Dashboard'!C70 -> 1.9229842 | D28: =AVERAGE($C$17:$C$28) -> 1.6009708 | G28: December | H28: ='User Dashboard'!E70 -> 1.8963378 | I28: ='User Dashboard'!F70 -> 1.9229842 | J28: ='User Dashboard'!G70 -> 1.9697677 | K28: ='User Dashboard'!H70 -> 2.0063843 | L28: ='User Dashboard'!I70 -> 2.042426 | M28: ='User Dashboard'!J70 -> 2.0789325 | N28: ='User Dashboard'!K70 -> 2.1159039 | O28: ='User Dashboard'!L70 -> 2.1532458 | ... AM28: ='User Dashboard'!AJ70 -> 3.2517979
B51: Chart titles:
B52: =C15&": "&C5&", "&C6&", "&C7&", "&C8 -> Levelized Gas Avoided Costs: SDG&E, Total Core, Small Boiler (<100MMBtu/Hr), Uncontrolled
B53: =H15&": "&C5&", "&C6&", "&C7&", "&C8 -> Monthly Gas Avoided Costs: SDG&E, Total Core, Small Boiler (<100MMBtu/Hr), Uncontrolled

Sheet Commodity
B2: Gas Commodity Costs ($/MMBtu)
B4: CA Gas Price Forecast ($/MMBtu) ($Nominal) | C4: ='User Dashboard'!E$58 -> 2023 | D4: ='User Dashboard'!F$58 -> 2024 | E4: ='User Dashboard'!G$58 -> 2025 | F4: ='User Dashboard'!H$58 -> 2026 | G4: ='User Dashboard'!I$58 -> 2027 | H4: ='User Dashboard'!J$58 -> 2028 | I4: ='User Dashboard'!K$58 -> 2029 | J4: ='User Dashboard'!L$58 -> 2030 | ... AH4: ='User Dashboard'!AJ$58 -> 2054
B5: 36526 | C5: ='IEPR Gas Prices Nominal'!T6 -> 5.8063148 | D5: ='IEPR Gas Prices Nominal'!U6 -> 5.7880168 | E5: ='IEPR Gas Prices Nominal'!V6 -> 5.9385103 | F5: ='IEPR Gas Prices Nominal'!W6 -> 6.0746326 | G5: ='IEPR Gas Prices Nominal'!X6 -> 6.1995546 | H5: ='IEPR Gas Prices Nominal'!Y6 -> 6.3245975 | I5: ='IEPR Gas Prices Nominal'!Z6 -> 6.4528316 | J5: ='IEPR Gas Prices Nominal'!AA6 -> 6.5841668 | ... AH5: ='IEPR Gas Prices Nominal'!AY6 -> 10.930327
B6: 36557 | C6: ='IEPR Gas Prices Nominal'!T7 -> 5.6657735 | D6: ='IEPR Gas Prices Nominal'!U7 -> 5.66267 | E6: ='IEPR Gas Prices Nominal'!V7 -> 5.8084916 | F6: ='IEPR Gas Prices Nominal'!W7 -> 5.9412448 | G6: ='IEPR Gas Prices Nominal'!X7 -> 6.0633526 | H6: ='IEPR Gas Prices Nominal'!Y7 -> 6.1857897 | I6: ='IEPR Gas Prices Nominal'!Z7 -> 6.3112829 | J6: ='IEPR Gas Prices Nominal'!AA7 -> 6.4396653 | ... AH6: ='IEPR Gas Prices Nominal'!AY7 -> 10.690843
B7: 36586 | C7: ='IEPR Gas Prices Nominal'!T8 -> 5.1890417 | D7: ='IEPR Gas Prices Nominal'!U8 -> 5.1997741 | E7: ='IEPR Gas Prices Nominal'!V8 -> 5.3323788 | F7: ='IEPR Gas Prices Nominal'!W8 -> 5.4538935 | G7: ='IEPR Gas Prices Nominal'!X8 -> 5.5659196 | H7: ='IEPR Gas Prices Nominal'!Y8 -> 5.6784419 | I7: ='IEPR Gas Prices Nominal'!Z8 -> 5.7937098 | J7: ='IEPR Gas Prices Nominal'!AA8 -> 5.9114979 | ... AH7: ='IEPR Gas Prices Nominal'!AY8 -> 9.8143723
B8: 36617 | C8: ='IEPR Gas Prices Nominal'!T9 -> 5.0888001 | D8: ='IEPR Gas Prices Nominal'!U9 -> 5.1127013 | E8: ='IEPR Gas Prices Nominal'!V9 -> 5.2418111 | F8: ='IEPR Gas Prices Nominal'!W9 -> 5.3609111 | G8: ='IEPR Gas Prices Nominal'!X9 -> 5.470963 | H8: ='IEPR Gas Prices Nominal'!Y9 -> 5.5816934 | I8: ='IEPR Gas Prices Nominal'!Z9 -> 5.6950636 | J8: ='IEPR Gas Prices Nominal'!AA9 -> 5.8107813 | ... AH8: ='IEPR Gas Prices Nominal'!AY9 -> 9.6475235
B9: 36647 | C9: ='IEPR Gas Prices Nominal'!T10 -> 5.2535408 | D9: ='IEPR Gas Prices Nominal'!U10 -> 5.2920912 | E9: ='IEPR Gas Prices Nominal'!V10 -> 5.4244125 | F9: ='IEPR Gas Prices Nominal'!W10 -> 5.5472983 | G9: ='IEPR Gas Prices Nominal'!X10 -> 5.66111 | H9: ='IEPR Gas Prices Nominal'!Y10 -> 5.775821 | I9: ='IEPR Gas Prices Nominal'!Z10 -> 5.8932028 | J9: ='IEPR Gas Prices Nominal'!AA10 -> 6.0128794 | ... AH9: ='IEPR Gas Prices Nominal'!AY10 -> 9.983438
B10: 36678 | C10: ='IEPR Gas Prices Nominal'!T11 -> 5.3766711 | D10: ='IEPR Gas Prices Nominal'!U11 -> 5.4303937 | E10: ='IEPR Gas Prices Nominal'!V11 -> 5.5648209 | F10: ='IEPR Gas Prices Nominal'!W11 -> 5.690515 | G10: ='IEPR Gas Prices Nominal'!X11 -> 5.8071968 | H10: ='IEPR Gas Prices Nominal'!Y11 -> 5.9250034 | I10: ='IEPR Gas Prices Nominal'!Z11 -> 6.0454874 | J10: ='IEPR Gas Prices Nominal'!AA11 -> 6.1681877 | ... AH10: ='IEPR Gas Prices Nominal'!AY11 -> 10.241688
B11: 36708 | C11: ='IEPR Gas Prices Nominal'!T12 -> 5.4065406 | D11: ='IEPR Gas Prices Nominal'!U12 -> 5.4749788 | E11: ='IEPR Gas Prices Nominal'!V12 -> 5.6091468 | F11: ='IEPR Gas Prices Nominal'!W12 -> 5.7354667 | G11: ='IEPR Gas Prices Nominal'!X12 -> 5.8530014 | H11: ='IEPR Gas Prices Nominal'!Y12 -> 5.9718739 | I11: ='IEPR Gas Prices Nominal'!Z12 -> 6.0933819 | J11: ='IEPR Gas Prices Nominal'!AA12 -> 6.2169849 | ... AH11: ='IEPR Gas Prices Nominal'!AY12 -> 10.323099
B12: 36739 | C12: ='IEPR Gas Prices Nominal'!T13 -> 5.3520919 | D12: ='IEPR Gas Prices Nominal'!U13 -> 5.4341815 | E12: ='IEPR Gas Prices Nominal'!V13 -> 5.5659978 | F12: ='IEPR Gas Prices Nominal'!W13 -> 5.6909733 | G12: ='IEPR Gas Prices Nominal'!X13 -> 5.807528 | H12: ='IEPR Gas Prices Nominal'!Y13 -> 5.9256125 | I12: ='IEPR Gas Prices Nominal'!Z13 -> 6.0462497 | J12: ='IEPR Gas Prices Nominal'!AA13 -> 6.1688277 | ... AH12: ='IEPR Gas Prices Nominal'!AY13 -> 10.243521
B13: 36770 | C13: ='IEPR Gas Prices Nominal'!T14 -> 5.414506 | D13: ='IEPR Gas Prices Nominal'!U14 -> 5.5121311 | E13: ='IEPR Gas Prices Nominal'!V14 -> 5.6444675 | F13: ='IEPR Gas Prices Nominal'!W14 -> 5.770827 | G13: ='IEPR Gas Prices Nominal'!X14 -> 5.8889479 | H13: ='IEPR Gas Prices Nominal'!Y14 -> 6.0088255 | I13: ='IEPR Gas Prices Nominal'!Z14 -> 6.1312282 | J13: ='IEPR Gas Prices Nominal'!AA14 -> 6.2554591 | ... AH13: ='IEPR Gas Prices Nominal'!AY14 -> 10.387765
B14: 36800 | C14: ='IEPR Gas Prices Nominal'!T15 -> 5.3705103 | D14: ='IEPR Gas Prices Nominal'!U15 -> 5.4818719 | E14: ='IEPR Gas Prices Nominal'!V15 -> 5.6121192 | F14: ='IEPR Gas Prices Nominal'!W15 -> 5.7373789 | G14: ='IEPR Gas Prices Nominal'!X15 -> 5.8547463 | H14: ='IEPR Gas Prices Nominal'!Y15 -> 5.9740645 | I14: ='IEPR Gas Prices Nominal'!Z15 -> 6.0958301 | J14: ='IEPR Gas Prices Nominal'!AA15 -> 6.2192743 | ... AH14: ='IEPR Gas Prices Nominal'!AY15 -> 10.328066
B15: 36831 | C15: ='IEPR Gas Prices Nominal'!T16 -> 5.6225295 | D15: ='IEPR Gas Prices Nominal'!U16 -> 5.7544026 | E15: ='IEPR Gas Prices Nominal'!V16 -> 5.8896954 | F15: ='IEPR Gas Prices Nominal'!W16 -> 6.0207562 | G15: ='IEPR Gas Prices Nominal'!X16 -> 6.1438483 | H15: ='IEPR Gas Prices Nominal'!Y16 -> 6.2692018 | I15: ='IEPR Gas Prices Nominal'!Z16 -> 6.3970575 | J15: ='IEPR Gas Prices Nominal'!AA16 -> 6.5265289 | ... AH15: ='IEPR Gas Prices Nominal'!AY16 -> 10.838717
B16: 36861 | C16: ='IEPR Gas Prices Nominal'!T17 -> 5.6542169 | D16: ='IEPR Gas Prices Nominal'!U17 -> 5.8022798 | E16: ='IEPR Gas Prices Nominal'!V17 -> 5.9372574 | F16: ='IEPR Gas Prices Nominal'!W17 -> 6.0689791 | G16: ='IEPR Gas Prices Nominal'!X17 -> 6.1929842 | H16: ='IEPR Gas Prices Nominal'!Y17 -> 6.319485 | I16: ='IEPR Gas Prices Nominal'!Z17 -> 6.4484413 | J16: ='IEPR Gas Prices Nominal'!AA17 -> 6.5788791 | ... AH16: ='IEPR Gas Prices Nominal'!AY17 -> 10.926067
B18: CA Gas Price Forecast ($/MMBtu) ($2022) | C18: ='User Dashboard'!E$58 -> 2023 | D18: ='User Dashboard'!F$58 -> 2024 | E18: ='User Dashboard'!G$58 -> 2025 | F18: ='User Dashboard'!H$58 -> 2026 | G18: ='User Dashboard'!I$58 -> 2027 | H18: ='User Dashboard'!J$58 -> 2028 | I18: ='User Dashboard'!K$58 -> 2029 | J18: ='User Dashboard'!L$58 -> 2030 | ... AH18: ='User Dashboard'!AJ$58 -> 2054
B19: 36526 | C19: ='IEPR Gas Prices Real'!T6 -> 5.6743612 | D19: ='IEPR Gas Prices Real'!U6 -> 5.5275616 | E19: ='IEPR Gas Prices Real'!V6 -> 5.5416814 | F19: ='IEPR Gas Prices Real'!W6 -> 5.5406483 | G19: ='IEPR Gas Prices Real'!X6 -> 5.5355627 | H19: ='IEPR Gas Prices Real'!Y6 -> 5.5298933 | I19: ='IEPR Gas Prices Real'!Z6 -> 5.5256846 | J19: ='IEPR Gas Prices Real'!AA6 -> 5.5221248 | ... AH19: ='IEPR Gas Prices Real'!AY6 -> 5.4298282
B20: 36557 | C20: ='IEPR Gas Prices Real'!T7 -> 5.5370138 | D20: ='IEPR Gas Prices Real'!U7 -> 5.4078553 | E20: ='IEPR Gas Prices Real'!V7 -> 5.420351 | F20: ='IEPR Gas Prices Real'!W7 -> 5.4189859 | G20: ='IEPR Gas Prices Real'!X7 -> 5.4139484 | H20: ='IEPR Gas Prices Real'!Y7 -> 5.4085271 | I20: ='IEPR Gas Prices Real'!Z7 -> 5.4044737 | J20: ='IEPR Gas Prices Real'!AA7 -> 5.4009318 | ... AH20: ='IEPR Gas Prices Real'!AY7 -> 5.3108603
B21: 36586 | C21: ='IEPR Gas Prices Real'!T8 -> 5.0711162 | D21: ='IEPR Gas Prices Real'!U8 -> 4.9657893 | E21: ='IEPR Gas Prices Real'!V8 -> 4.9760534 | F21: ='IEPR Gas Prices Real'!W8 -> 4.9744747 | G21: ='IEPR Gas Prices Real'!X8 -> 4.969792 | H21: ='IEPR Gas Prices Real'!Y8 -> 4.9649291 | I21: ='IEPR Gas Prices Real'!Z8 -> 4.9612659 | J21: ='IEPR Gas Prices Real'!AA8 -> 4.957959 | ... AH21: ='IEPR Gas Prices Real'!AY8 -> 4.8754583
B22: 36617 | C22: ='IEPR Gas Prices Real'!T9 -> 4.9731527 | D22: ='IEPR Gas Prices Real'!U9 -> 4.8826347 | E22: ='IEPR Gas Prices Real'!V9 -> 4.8915378 | F22: ='IEPR Gas Prices Real'!W9 -> 4.8896658 | G22: ='IEPR Gas Prices Real'!X9 -> 4.8850056 | H22: ='IEPR Gas Prices Real'!Y9 -> 4.8803373 | I22: ='IEPR Gas Prices Real'!Z9 -> 4.8767932 | J22: ='IEPR Gas Prices Real'!AA9 -> 4.8734883 | ... AH22: ='IEPR Gas Prices Real'!AY9 -> 4.7925732
B23: 36647 | C23: ='IEPR Gas Prices Real'!T10 -> 5.1341495 | D23: ='IEPR Gas Prices Real'!U10 -> 5.0539521 | E23: ='IEPR Gas Prices Real'!V10 -> 5.0619372 | F23: ='IEPR Gas Prices Real'!W10 -> 5.0596689 | G23: ='IEPR Gas Prices Real'!X10 -> 5.0547872 | H23: ='IEPR Gas Prices Real'!Y10 -> 5.0500722 | I23: ='IEPR Gas Prices Real'!Z10 -> 5.0464636 | J23: ='IEPR Gas Prices Real'!AA10 -> 5.0429874 | ... AH23: ='IEPR Gas Prices Real'!AY10 -> 4.9594445
B24: 36678 | C24: ='IEPR Gas Prices Real'!T11 -> 5.2544816 | D24: ='IEPR Gas Prices Real'!U11 -> 5.1860312 | E24: ='IEPR Gas Prices Real'!V11 -> 5.1929631 | F24: ='IEPR Gas Prices Real'!W11 -> 5.1902962 | G24: ='IEPR Gas Prices Real'!X11 -> 5.1852276 | H24: ='IEPR Gas Prices Real'!Y11 -> 5.1805094 | I24: ='IEPR Gas Prices Real'!Z11 -> 5.176868 | J24: ='IEPR Gas Prices Real'!AA11 -> 5.1732441 | ... AH24: ='IEPR Gas Prices Real'!AY11 -> 5.0877347
B25: 36708 | C25: ='IEPR Gas Prices Real'!T12 -> 5.2836723 | D25: ='IEPR Gas Prices Real'!U12 -> 5.22861 | E25: ='IEPR Gas Prices Real'!V12 -> 5.234327 | F25: ='IEPR Gas Prices Real'!W12 -> 5.2312965 | G25: ='IEPR Gas Prices Real'!X12 -> 5.2261264 | H25: ='IEPR Gas Prices Real'!Y12 -> 5.2214905 | I25: ='IEPR Gas Prices Real'!Z12 -> 5.2178809 | J25: ='IEPR Gas Prices Real'!AA12 -> 5.2141702 | ... AH25: ='IEPR Gas Prices Real'!AY12 -> 5.1281771
B26: 36739 | C26: ='IEPR Gas Prices Real'!T13 -> 5.2304609 | D26: ='IEPR Gas Prices Real'!U13 -> 5.1896486 | E26: ='IEPR Gas Prices Real'!V13 -> 5.1940613 | F26: ='IEPR Gas Prices Real'!W13 -> 5.1907142 | G26: ='IEPR Gas Prices Real'!X13 -> 5.1855233 | H26: ='IEPR Gas Prices Real'!Y13 -> 5.181042 | I26: ='IEPR Gas Prices Real'!Z13 -> 5.1775207 | J26: ='IEPR Gas Prices Real'!AA13 -> 5.1737809 | ... AH26: ='IEPR Gas Prices Real'!AY13 -> 5.0886452
B27: 36770 | C27: ='IEPR Gas Prices Real'!T14 -> 5.2914566 | D27: ='IEPR Gas Prices Real'!U14 -> 5.2640905 | E27: ='IEPR Gas Prices Real'!V14 -> 5.2672874 | F27: ='IEPR Gas Prices Real'!W14 -> 5.2635485 | G27: ='IEPR Gas Prices Real'!X14 -> 5.258223 | H27: ='IEPR Gas Prices Real'!Y14 -> 5.253799 | I27: ='IEPR Gas Prices Real'!Z14 -> 5.2502895 | J27: ='IEPR Gas Prices Real'!AA14 -> 5.2464385 | ... AH27: ='IEPR Gas Prices Real'!AY14 -> 5.1603012
B28: 36800 | C28: ='IEPR Gas Prices Real'!T15 -> 5.2484607 | D28: ='IEPR Gas Prices Real'!U15 -> 5.235193 | E28: ='IEPR Gas Prices Real'!V15 -> 5.2371008 | F28: ='IEPR Gas Prices Real'!W15 -> 5.2330406 | G28: ='IEPR Gas Prices Real'!X15 -> 5.2276845 | H28: ='IEPR Gas Prices Real'!Y15 -> 5.2234058 | I28: ='IEPR Gas Prices Real'!Z15 -> 5.2199773 | J28: ='IEPR Gas Prices Real'!AA15 -> 5.2160903 | ... AH28: ='IEPR Gas Prices Real'!AY15 -> 5.1306442
B29: 36831 | C29: ='IEPR Gas Prices Real'!T16 -> 5.4947526 | D29: ='IEPR Gas Prices Real'!U16 -> 5.49546 | E29: ='IEPR Gas Prices Real'!V16 -> 5.4961285 | F29: ='IEPR Gas Prices Real'!W16 -> 5.4915079 | G29: ='IEPR Gas Prices Real'!X16 -> 5.4858227 | H29: ='IEPR Gas Prices Real'!Y16 -> 5.4814582 | I29: ='IEPR Gas Prices Real'!Z16 -> 5.4779242 | J29: ='IEPR Gas Prices Real'!AA16 -> 5.473784 | ... AH29: ='IEPR Gas Prices Real'!AY16 -> 5.384319
B30: 36861 | C30: ='IEPR Gas Prices Real'!T17 -> 5.5257199 | D30: ='IEPR Gas Prices Real'!U17 -> 5.5411828 | E30: ='IEPR Gas Prices Real'!V17 -> 5.5405123 | F30: ='IEPR Gas Prices Real'!W17 -> 5.5354918 | G30: ='IEPR Gas Prices Real'!X17 -> 5.529696 | H30: ='IEPR Gas Prices Real'!Y17 -> 5.5254232 | I30: ='IEPR Gas Prices Real'!Z17 -> 5.5219252 | J30: ='IEPR Gas Prices Real'!AA17 -> 5.51769 | ... AH30: ='IEPR Gas Prices Real'!AY17 -> 5.4277116
B33: Gas Commodity Costs ($/therm)
B35: CA Gas Price Forecast ($/therm) ($Nominal) | C35: ='User Dashboard'!E$58 -> 2023 | D35: ='User Dashboard'!F$58 -> 2024 | E35: ='User Dashboard'!G$58 -> 2025 | F35: ='User Dashboard'!H$58 -> 2026 | G35: ='User Dashboard'!I$58 -> 2027 | H35: ='User Dashboard'!J$58 -> 2028 | I35: ='User Dashboard'!K$58 -> 2029 | J35: ='User Dashboard'!L$58 -> 2030 | ... AH35: ='User Dashboard'!AJ$58 -> 2054
B36: 36526 | C36: =C5/'Other Inputs'!$C$22 -> 0.58063148 | D36: =D5/'Other Inputs'!$C$22 -> 0.57880168 | E36: =E5/'Other Inputs'!$C$22 -> 0.59385103 | F36: =F5/'Other Inputs'!$C$22 -> 0.60746326 | G36: =G5/'Other Inputs'!$C$22 -> 0.61995546 | H36: =H5/'Other Inputs'!$C$22 -> 0.63245975 | I36: =I5/'Other Inputs'!$C$22 -> 0.64528316 | J36: =J5/'Other Inputs'!$C$22 -> 0.65841668 | ... AH36: =AH5/'Other Inputs'!$C$22 -> 1.0930327
B37: 36557 | C37: =C6/'Other Inputs'!$C$22 -> 0.56657735 | D37: =D6/'Other Inputs'!$C$22 -> 0.566267 | E37: =E6/'Other Inputs'!$C$22 -> 0.58084916 | F37: =F6/'Other Inputs'!$C$22 -> 0.59412448 | G37: =G6/'Other Inputs'!$C$22 -> 0.60633526 | H37: =H6/'Other Inputs'!$C$22 -> 0.61857897 | I37: =I6/'Other Inputs'!$C$22 -> 0.63112829 | J37: =J6/'Other Inputs'!$C$22 -> 0.64396653 | ... AH37: =AH6/'Other Inputs'!$C$22 -> 1.0690843
B38: 36586 | C38: =C7/'Other Inputs'!$C$22 -> 0.51890417 | D38: =D7/'Other Inputs'!$C$22 -> 0.51997741 | E38: =E7/'Other Inputs'!$C$22 -> 0.53323788 | F38: =F7/'Other Inputs'!$C$22 -> 0.54538935 | G38: =G7/'Other Inputs'!$C$22 -> 0.55659196 | H38: =H7/'Other Inputs'!$C$22 -> 0.56784419 | I38: =I7/'Other Inputs'!$C$22 -> 0.57937098 | J38: =J7/'Other Inputs'!$C$22 -> 0.59114979 | ... AH38: =AH7/'Other Inputs'!$C$22 -> 0.98143723
B39: 36617 | C39: =C8/'Other Inputs'!$C$22 -> 0.50888001 | D39: =D8/'Other Inputs'!$C$22 -> 0.51127013 | E39: =E8/'Other Inputs'!$C$22 -> 0.52418111 | F39: =F8/'Other Inputs'!$C$22 -> 0.53609111 | G39: =G8/'Other Inputs'!$C$22 -> 0.5470963 | H39: =H8/'Other Inputs'!$C$22 -> 0.55816934 | I39: =I8/'Other Inputs'!$C$22 -> 0.56950636 | J39: =J8/'Other Inputs'!$C$22 -> 0.58107813 | ... AH39: =AH8/'Other Inputs'!$C$22 -> 0.96475235
B40: 36647 | C40: =C9/'Other Inputs'!$C$22 -> 0.52535408 | D40: =D9/'Other Inputs'!$C$22 -> 0.52920912 | E40: =E9/'Other Inputs'!$C$22 -> 0.54244125 | F40: =F9/'Other Inputs'!$C$22 -> 0.55472983 | G40: =G9/'Other Inputs'!$C$22 -> 0.566111 | H40: =H9/'Other Inputs'!$C$22 -> 0.5775821 | I40: =I9/'Other Inputs'!$C$22 -> 0.58932028 | J40: =J9/'Other Inputs'!$C$22 -> 0.60128794 | ... AH40: =AH9/'Other Inputs'!$C$22 -> 0.9983438
B41: 36678 | C41: =C10/'Other Inputs'!$C$22 -> 0.53766711 | D41: =D10/'Other Inputs'!$C$22 -> 0.54303937 | E41: =E10/'Other Inputs'!$C$22 -> 0.55648209 | F41: =F10/'Other Inputs'!$C$22 -> 0.5690515 | G41: =G10/'Other Inputs'!$C$22 -> 0.58071968 | H41: =H10/'Other Inputs'!$C$22 -> 0.59250034 | I41: =I10/'Other Inputs'!$C$22 -> 0.60454874 | J41: =J10/'Other Inputs'!$C$22 -> 0.61681877 | ... AH41: =AH10/'Other Inputs'!$C$22 -> 1.0241688
B42: 36708 | C42: =C11/'Other Inputs'!$C$22 -> 0.54065406 | D42: =D11/'Other Inputs'!$C$22 -> 0.54749788 | E42: =E11/'Other Inputs'!$C$22 -> 0.56091468 | F42: =F11/'Other Inputs'!$C$22 -> 0.57354667 | G42: =G11/'Other Inputs'!$C$22 -> 0.58530014 | H42: =H11/'Other Inputs'!$C$22 -> 0.59718739 | I42: =I11/'Other Inputs'!$C$22 -> 0.60933819 | J42: =J11/'Other Inputs'!$C$22 -> 0.62169849 | ... AH42: =AH11/'Other Inputs'!$C$22 -> 1.0323099
B43: 36739 | C43: =C12/'Other Inputs'!$C$22 -> 0.53520919 | D43: =D12/'Other Inputs'!$C$22 -> 0.54341815 | E43: =E12/'Other Inputs'!$C$22 -> 0.55659978 | F43: =F12/'Other Inputs'!$C$22 -> 0.56909733 | G43: =G12/'Other Inputs'!$C$22 -> 0.5807528 | H43: =H12/'Other Inputs'!$C$22 -> 0.59256125 | I43: =I12/'Other Inputs'!$C$22 -> 0.60462497 | J43: =J12/'Other Inputs'!$C$22 -> 0.61688277 | ... AH43: =AH12/'Other Inputs'!$C$22 -> 1.0243521
B44: 36770 | C44: =C13/'Other Inputs'!$C$22 -> 0.5414506 | D44: =D13/'Other Inputs'!$C$22 -> 0.55121311 | E44: =E13/'Other Inputs'!$C$22 -> 0.56444675 | F44: =F13/'Other Inputs'!$C$22 -> 0.5770827 | G44: =G13/'Other Inputs'!$C$22 -> 0.58889479 | H44: =H13/'Other Inputs'!$C$22 -> 0.60088255 | I44: =I13/'Other Inputs'!$C$22 -> 0.61312282 | J44: =J13/'Other Inputs'!$C$22 -> 0.62554591 | ... AH44: =AH13/'Other Inputs'!$C$22 -> 1.0387765
B45: 36800 | C45: =C14/'Other Inputs'!$C$22 -> 0.53705103 | D45: =D14/'Other Inputs'!$C$22 -> 0.54818719 | E45: =E14/'Other Inputs'!$C$22 -> 0.56121192 | F45: =F14/'Other Inputs'!$C$22 -> 0.57373789 | G45: =G14/'Other Inputs'!$C$22 -> 0.58547463 | H45: =H14/'Other Inputs'!$C$22 -> 0.59740645 | I45: =I14/'Other Inputs'!$C$22 -> 0.60958301 | J45: =J14/'Other Inputs'!$C$22 -> 0.62192743 | ... AH45: =AH14/'Other Inputs'!$C$22 -> 1.0328066
B46: 36831 | C46: =C15/'Other Inputs'!$C$22 -> 0.56225295 | D46: =D15/'Other Inputs'!$C$22 -> 0.57544026 | E46: =E15/'Other Inputs'!$C$22 -> 0.58896954 | F46: =F15/'Other Inputs'!$C$22 -> 0.60207562 | G46: =G15/'Other Inputs'!$C$22 -> 0.61438483 | H46: =H15/'Other Inputs'!$C$22 -> 0.62692018 | I46: =I15/'Other Inputs'!$C$22 -> 0.63970575 | J46: =J15/'Other Inputs'!$C$22 -> 0.65265289 | ... AH46: =AH15/'Other Inputs'!$C$22 -> 1.0838717
...

Sheet Emissions
B2: Gas Emissions Values
B4: Gas Emissions Rates
B5: Combustor Type | C5: Controls | D5: NOx (lb/MMBtu) | E5: CO2 (lb/MMBtu) | F5: Nox (lbs / Therm) | G5: CO2 (Tonnes / Therm) | H5: Key
B6: Large Boiler (>100MMBtu/Hr) | C6: Uncontrolled | D6: 0.186 | E6: 117 | F6: =D6/10 -> 0.0186 | G6: =E6/(10*2204.62) -> 0.005307037 | H6: =_xlfn.CONCAT(B6,"-",C6) -> Large Boiler (>100MMBtu/Hr)-Uncontrolled
B7: Large Boiler (>100MMBtu/Hr) | C7: Low Nox Burner | D7: 0.137 | E7: 117 | F7: =D7/10 -> 0.0137 | G7: =E7/(10*2204.62) -> 0.005307037 | H7: =_xlfn.CONCAT(B7,"-",C7) -> Large Boiler (>100MMBtu/Hr)-Low Nox Burner
B8: Large Boiler (>100MMBtu/Hr) | C8: Flue Gas Recirculation | D8: 0.098 | E8: 117 | F8: =D8/10 -> 0.0098 | G8: =E8/(10*2204.62) -> 0.005307037 | H8: =_xlfn.CONCAT(B8,"-",C8) -> Large Boiler (>100MMBtu/Hr)-Flue Gas Recirculation
B9: Small Boiler (<100MMBtu/Hr) | C9: Uncontrolled | D9: 0.098 | E9: 117 | F9: =D9/10 -> 0.0098 | G9: =E9/(10*2204.62) -> 0.005307037 | H9: =_xlfn.CONCAT(B9,"-",C9) -> Small Boiler (<100MMBtu/Hr)-Uncontrolled
B10: Small Boiler (<100MMBtu/Hr) | C10: Low Nox Burner | D10: 0.049 | E10: 117 | F10: =D10/10 -> 0.0049 | G10: =E10/(10*2204.62) -> 0.005307037 | H10: =_xlfn.CONCAT(B10,"-",C10) -> Small Boiler (<100MMBtu/Hr)-Low Nox Burner
B11: Small Boiler (<100MMBtu/Hr) | C11: Flue Gas Recirculation | D11: 0.031 | E11: 117 | F11: =D11/10 -> 0.0031 | G11: =E11/(10*2204.62) -> 0.005307037 | H11: =_xlfn.CONCAT(B11,"-",C11) -> Small Boiler (<100MMBtu/Hr)-Flue Gas Recirculation
B12: Residential Furnace | C12: Uncontrolled | D12: 0.092 | E12: 117 | F12: =D12/10 -> 0.0092 | G12: =E12/(10*2204.62) -> 0.005307037 | H12: =_xlfn.CONCAT(B12,"-",C12) -> Residential Furnace-Uncontrolled
B16: Gas Emissions Costs - TRC | C16: 2019 | D16: 2020 | E16: 2021 | F16: 2022 | G16: 2023 | H16: =G16+1 -> 2024 | I16: =H16+1 -> 2025 | J16: =I16+1 -> 2026 | K16: =J16+1 -> 2027 | L16: =K16+1 -> 2028 | M16: =L16+1 -> 2029 | N16: =M16+1 -> 2030 | O16: =N16+1 -> 2031 | ... AF16: =AE16+1 -> 2048 | AG16: 2049 | AH16: 2050 | AI16: 2051 | AJ16: 2052 | AK16: 2053 | AL16: 2054
B17: NOx (nominal $/lb) | C17: 11.339585 | D17: 12.473543 | E17: 13.720898 | F17: 15.092987 | G17: 16.602286 | H17: =TREND($C17:$G17,$C$16:$G$16,H$16) -> 17.789314 | I17: =TREND($C17:$G17,$C$16:$G$16,I$16) -> 19.103799 | J17: =TREND($C17:$G17,$C$16:$G$16,J$16) -> 20.418283 | K17: =TREND($C17:$G17,$C$16:$G$16,K$16) -> 21.732768 | L17: =TREND($C17:$G17,$C$16:$G$16,L$16) -> 23.047253 | M17: =TREND($C17:$G17,$C$16:$G$16,M$16) -> 24.361737 | N17: =TREND($C17:$G17,$C$16:$G$16,N$16) -> 25.676222 | O17: =TREND($C17:$G17,$C$16:$G$16,O$16) -> 26.990707 | ... AL17: =TREND($C17:$G17,$C$16:$G$16,AL$16) -> 57.223854
B18: NOx (nominal $/therm) | C18: =C17*'User Dashboard'!$C$34 -> 0.11112793 | D18: =D17*'User Dashboard'!$C$34 -> 0.12224072 | E18: =E17*'User Dashboard'!$C$34 -> 0.1344648 | F18: =F17*'User Dashboard'!$C$34 -> 0.14791128 | G18: =G17*'User Dashboard'!$C$34 -> 0.1627024 | H18: =H17*'User Dashboard'!$C$34 -> 0.17433528 | I18: =I17*'User Dashboard'!$C$34 -> 0.18721723 | J18: =J17*'User Dashboard'!$C$34 -> 0.20009918 | ... AL18: =AL17*'User Dashboard'!$C$34 -> 0.56079377
B19: CO2 (nominal $/tonne) | C19: =$D$19*(1+'Other Inputs'!$C$18)^(Emissions!C$16-2020) -> 114 | D19: 114 | E19: =$D$19*(1+'Other Inputs'!$C$18)^(Emissions!E$16-2020) -> 114 | F19: =$D$19*(1+'Other Inputs'!$C$18)^(Emissions!F$16-2020) -> 114 | G19: =$D$19*(1+'Other Inputs'!$C$18)^(Emissions!G$16-2020) -> 114 | H19: =$D$19*(1+'Other Inputs'!$C$18)^(Emissions!H$16-2020) -> 114 | I19: =$D$19*(1+'Other Inputs'!$C$18)^(Emissions!I$16-2020) -> 114 | J19: =$D$19*(1+'Other Inputs'!$C$18)^(Emissions!J$16-2020) -> 114 | K19: =$D$19*(1+'Other Inputs'!$C$18)^(Emissions!K$16-2020) -> 114 | L19: =$D$19*(1+'Other Inputs'!$C$18)^(Emissions!L$16-2020) -> 114 | ... AL19: =$D$19*(1+'Other Inputs'!$C$18)^(Emissions!AL$16-2020) -> 114
B20: PM10 (nominal $/lb) | C20: 15.86307 | D20: 17.449377 | E20: 19.194314 | F20: 21.113746 | G20: 23.22512 | H20: =TREND($C20:$G20,$C$16:$G$16,H$16) -> 24.885666 | I20: =TREND($C20:$G20,$C$16:$G$16,I$16) -> 26.724513 | J20: =TREND($C20:$G20,$C$16:$G$16,J$16) -> 28.563361 | K20: =TREND($C20:$G20,$C$16:$G$16,K$16) -> 30.402208 | L20: =TREND($C20:$G20,$C$16:$G$16,L$16) -> 32.241055 | M20: =TREND($C20:$G20,$C$16:$G$16,M$16) -> 34.079902 | N20: =TREND($C20:$G20,$C$16:$G$16,N$16) -> 35.918749 | O20: =TREND($C20:$G20,$C$16:$G$16,O$16) -> 37.757596 | ... AL20: =TREND($C20:$G20,$C$16:$G$16,AL$16) -> 80.051078
B22: Gas Emissions Costs - SCT | D22: 2020 | E22: 2021 | F22: 2022 | G22: 2023 | H22: =G22+1 -> 2024 | I22: =H22+1 -> 2025 | J22: =I22+1 -> 2026 | K22: =J22+1 -> 2027 | L22: =K22+1 -> 2028 | M22: =L22+1 -> 2029 | N22: =M22+1 -> 2030 | O22: =N22+1 -> 2031 | ... AF22: =AE22+1 -> 2048 | AG22: 2049 | AH22: 2050 | AI22: 2051 | AJ22: 2052 | AK22: 2053 | AL22: 2054
B23: Air Quality Adder (2020 $/therm) | D23: 1.23 | E23: =D23 -> 1.23 | F23: =E23 -> 1.23 | G23: =F23 -> 1.23 | H23: =G23 -> 1.23 | I23: =H23 -> 1.23 | J23: =I23 -> 1.23 | K23: =J23 -> 1.23 | L23: =K23 -> 1.23 | ... AL23: =AK23 -> 1.23
B24: Air Quality Adder (nominal $/therm) | D24: =D23*(1+'Other Inputs'!$C$11)^(Emissions!D22-2020) -> 1.23 | E24: =E23*(1+'Other Inputs'!$C$11)^(Emissions!E22-2020) -> 1.2546 | F24: =F23*(1+'Other Inputs'!$C$11)^(Emissions!F22-2020) -> 1.279692 | G24: =G23*(1+'Other Inputs'!$C$11)^(Emissions!G22-2020) -> 1.3052858 | H24: =H23*(1+'Other Inputs'!$C$11)^(Emissions!H22-2020) -> 1.3313916 | I24: =I23*(1+'Other Inputs'!$C$11)^(Emissions!I22-2020) -> 1.3580194 | J24: =J23*(1+'Other Inputs'!$C$11)^(Emissions!J22-2020) -> 1.3851798 | K24: =K23*(1+'Other Inputs'!$C$11)^(Emissions!K22-2020) -> 1.4128834 | ... AL24: =AL23*(1+'Other Inputs'!$C$11)^(Emissions!AL22-2020) -> 2.4116315
B25: Social Cost of Carbon Base (2020 $/tonne) | D25: 51 | E25: =D25+($I25-$D25)/($I$22-$D$22) -> 52 | F25: =E25+($I25-$D25)/($I$22-$D$22) -> 53 | G25: =F25+($I25-$D25)/($I$22-$D$22) -> 54 | H25: =G25+($I25-$D25)/($I$22-$D$22) -> 55 | I25: 56 | J25: =I25+($N25-$I25)/($N$22-$I$22) -> 57.2 | K25: =J25+($N25-$I25)/($N$22-$I$22) -> 58.4 | L25: =K25+($N25-$I25)/($N$22-$I$22) -> 59.6 | M25: =L25+($N25-$I25)/($N$22-$I$22) -> 60.8 | N25: 62 | O25: =N25+($S25-$N25)/($S$22-$N$22) -> 63 | P25: =O25+($S25-$N25)/($S$22-$N$22) -> 64 | Q25: =P25+($S25-$N25)/($S$22-$N$22) -> 65 | R25: =Q25+($S25-$N25)/($S$22-$N$22) -> 66 | S25: 67 | T25: =S25+($X25-$S25)/($X$22-$S$22) -> 68.2 | U25: =T25+($X25-$S25)/($X$22-$S$22) -> 69.4 | V25: =U25+($X25-$S25)/($X$22-$S$22) -> 70.6 | W25: =V25+($X25-$S25)/($X$22-$S$22) -> 71.8 | X25: 73 | Y25: =X25+($AC25-$X25)/($AC$22-$X$22) -> 74.2 | Z25: =Y25+($AC25-$X25)/($AC$22-$X$22) -> 75.4 | AA25: =Z25+($AC25-$X25)/($AC$22-$X$22) -> 76.6 | AB25: =AA25+($AC25-$X25)/($AC$22-$X$22) -> 77.8 | AC25: 79 | AD25: =AC25+($AC25-$X25)/($AC$22-$X$22) -> 80.2 | AE25: =AD25+($AC25-$X25)/($AC$22-$X$22) -> 81.4 | AF25: =AE25+($AC25-$X25)/($AC$22-$X$22) -> 82.6 | AG25: =AF25+($AC25-$X25)/($AC$22-$X$22) -> 83.8 | AH25: =AG25+($AC25-$X25)/($AC$22-$X$22) -> 85 | AI25: =AH25+($AC25-$X25)/($AC$22-$X$22) -> 86.2 | AJ25: =AI25+($AC25-$X25)/($AC$22-$X$22) -> 87.4 | AK25: =AJ25+($AC25-$X25)/($AC$22-$X$22) -> 88.6 | AL25: =AK25+($AC25-$X25)/($AC$22-$X$22) -> 89.8
B26: Social Cost of Carbon High (2020 $/tonne) | D26: 152 | E26: =D26+($I26-$D26)/($I$22-$D$22) -> 155.4 | F26: =E26+($I26-$D26)/($I$22-$D$22) -> 158.8 | G26: =F26+($I26-$D26)/($I$22-$D$22) -> 162.2 | H26: =G26+($I26-$D26)/($I$22-$D$22) -> 165.6 | I26: 169 | J26: =I26+($N26-$I26)/($N$22-$I$22) -> 172.6 | K26: =J26+($N26-$I26)/($N$22-$I$22) -> 176.2 | L26: =K26+($N26-$I26)/($N$22-$I$22) -> 179.8 | M26: =L26+($N26-$I26)/($N$22-$I$22) -> 183.4 | N26: 187 | O26: =N26+($S26-$N26)/($S$22-$N$22) -> 190.8 | P26: =O26+($S26-$N26)/($S$22-$N$22) -> 194.6 | Q26: =P26+($S26-$N26)/($S$22-$N$22) -> 198.4 | R26: =Q26+($S26-$N26)/($S$22-$N$22) -> 202.2 | S26: 206 | T26: =S26+($X26-$S26)/($X$22-$S$22) -> 209.8 | U26: =T26+($X26-$S26)/($X$22-$S$22) -> 213.6 | V26: =U26+($X26-$S26)/($X$22-$S$22) -> 217.4 | W26: =V26+($X26-$S26)/($X$22-$S$22) -> 221.2 | X26: 225 | Y26: =X26+($AC26-$X26)/($AC$22-$X$22) -> 228.4 | Z26: =Y26+($AC26-$X26)/($AC$22-$X$22) -> 231.8 | AA26: =Z26+($AC26-$X26)/($AC$22-$X$22) -> 235.2 | AB26: =AA26+($AC26-$X26)/($AC$22-$X$22) -> 238.6 | AC26: 242 | AD26: =AC26+($AC26-$X26)/($AC$22-$X$22) -> 245.4 | AE26: =AD26+($AC26-$X26)/($AC$22-$X$22) -> 248.8 | AF26: =AE26+($AC26-$X26)/($AC$22-$X$22) -> 252.2 | AG26: =AF26+($AC26-$X26)/($AC$22-$X$22) -> 255.6 | AH26: =AG26+($AC26-$X26)/($AC$22-$X$22) -> 259 | AI26: =AH26+($AC26-$X26)/($AC$22-$X$22) -> 262.4 | AJ26: =AI26+($AC26-$X26)/($AC$22-$X$22) -> 265.8 | AK26: =AJ26+($AC26-$X26)/($AC$22-$X$22) -> 269.2 | AL26: =AK26+($AC26-$X26)/($AC$22-$X$22) -> 272.6
B27: Social Cost of Carbon Base (nominal $/tonne) | D27: =D25*(1+'Other Inputs'!$C$11)^(D22-2020) -> 51 | E27: =E25*(1+'Other Inputs'!$C$11)^(E22-2020) -> 53.04 | F27: =F25*(1+'Other Inputs'!$C$11)^(F22-2020) -> 55.1412 | G27: =G25*(1+'Other Inputs'!$C$11)^(G22-2020) -> 57.305232 | H27: =H25*(1+'Other Inputs'!$C$11)^(H22-2020) -> 59.533769 | I27: =I25*(1+'Other Inputs'!$C$11)^(I22-2020) -> 61.828525 | J27: =J25*(1+'Other Inputs'!$C$11)^(J22-2020) -> 64.41649 | K27: =K25*(1+'Other Inputs'!$C$11)^(K22-2020) -> 67.083243 | ... AL27: =AL25*(1+'Other Inputs'!$C$11)^(AL22-2020) -> 176.06871
B28: Social Cost of Carbon High (nominal $/tonne) | D28: =D26*(1+'Other Inputs'!$C$11)^(D22-2020) -> 152 | E28: =E26*(1+'Other Inputs'!$C$11)^(E22-2020) -> 158.508 | F28: =F26*(1+'Other Inputs'!$C$11)^(F22-2020) -> 165.21552 | G28: =G26*(1+'Other Inputs'!$C$11)^(G22-2020) -> 172.12794 | H28: =H26*(1+'Other Inputs'!$C$11)^(H22-2020) -> 179.25077 | I28: =I26*(1+'Other Inputs'!$C$11)^(I22-2020) -> 186.58966 | J28: =J26*(1+'Other Inputs'!$C$11)^(J22-2020) -> 194.37563 | K28: =K26*(1+'Other Inputs'!$C$11)^(K22-2020) -> 202.39841 | ... AL28: =AL26*(1+'Other Inputs'!$C$11)^(AL22-2020) -> 534.48029
B30: Gas Emissions Costs - Active | D30: 2020 | E30: 2021 | F30: 2022 | G30: 2023 | H30: 2024 | I30: 2025 | J30: 2026 | K30: 2027 | L30: 2028 | M30: 2029 | N30: 2030 | O30: 2031 | P30: 2032 | Q30: 2033 | R30: 2034 | S30: 2035 | T30: 2036 | U30: 2037 | V30: 2038 | W30: 2039 | X30: 2040 | Y30: 2041 | Z30: 2042 | AA30: 2043 | AB30: 2044 | AC30: 2045 | AD30: 2046 | AE30: 2047 | AF30: 2048 | AG30: 2049 | AH30: 2050 | AI30: 2051 | AJ30: 2052 | AK30: 2053 | AL30: 2054
B31: Air Quality Adder (nominal $/therm) | D31: =IF('User Dashboard'!$C$10="TRC",0,D24)*('User Dashboard'!$C$34/MAX(Emissions!$F$6:$F$12)) -> 0 | E31: =IF('User Dashboard'!$C$10="TRC",0,E24)*('User Dashboard'!$C$34/MAX(Emissions!$F$6:$F$12)) -> 0 | F31: =IF('User Dashboard'!$C$10="TRC",0,F24)*('User Dashboard'!$C$34/MAX(Emissions!$F$6:$F$12)) -> 0 | G31: =IF('User Dashboard'!$C$10="TRC",0,G24)*('User Dashboard'!$C$34/MAX(Emissions!$F$6:$F$12)) -> 0 | H31: =IF('User Dashboard'!$C$10="TRC",0,H24)*('User Dashboard'!$C$34/MAX(Emissions!$F$6:$F$12)) -> 0 | I31: =IF('User Dashboard'!$C$10="TRC",0,I24)*('User Dashboard'!$C$34/MAX(Emissions!$F$6:$F$12)) -> 0 | J31: =IF('User Dashboard'!$C$10="TRC",0,J24)*('User Dashboard'!$C$34/MAX(Emissions!$F$6:$F$12)) -> 0 | K31: =IF('User Dashboard'!$C$10="TRC",0,K24)*('User Dashboard'!$C$34/MAX(Emissions!$F$6:$F$12)) -> 0 | ... AL31: =IF('User Dashboard'!$C$10="TRC",0,AL24)*('User Dashboard'!$C$34/MAX(Emissions!$F$6:$F$12)) -> 0
B32: NOx Cost (nominal $/therm) | D32: =IF('User Dashboard'!$C$10="TRC",D18,0) -> 0.12224072 | E32: =IF('User Dashboard'!$C$10="TRC",E18,0) -> 0.1344648 | F32: =IF('User Dashboard'!$C$10="TRC",F18,0) -> 0.14791128 | G32: =IF('User Dashboard'!$C$10="TRC",G18,0) -> 0.1627024 | H32: =IF('User Dashboard'!$C$10="TRC",H18,0) -> 0.17433528 | I32: =IF('User Dashboard'!$C$10="TRC",I18,0) -> 0.18721723 | J32: =IF('User Dashboard'!$C$10="TRC",J18,0) -> 0.20009918 | K32: =IF('User Dashboard'!$C$10="TRC",K18,0) -> 0.21298113 | ... AL32: =IF('User Dashboard'!$C$10="TRC",AL18,0) -> 0.56079377
B33: CO2 Cost (nominal $/tonne) | D33: =IF('User Dashboard'!$C$10="TRC",D19,MAX(IF('User Dashboard'!$C$11="Base",D27,D28),D19)) -> 114 | E33: =IF('User Dashboard'!$C$10="TRC",E19,MAX(IF('User Dashboard'!$C$11="Base",E27,E28),E19)) -> 114 | F33: =IF('User Dashboard'!$C$10="TRC",F19,MAX(IF('User Dashboard'!$C$11="Base",F27,F28),F19)) -> 114 | G33: =IF('User Dashboard'!$C$10="TRC",G19,MAX(IF('User Dashboard'!$C$11="Base",G27,G28),G19)) -> 114 | H33: =IF('User Dashboard'!$C$10="TRC",H19,MAX(IF('User Dashboard'!$C$11="Base",H27,H28),H19)) -> 114 | I33: =IF('User Dashboard'!$C$10="TRC",I19,MAX(IF('User Dashboard'!$C$11="Base",I27,I28),I19)) -> 114 | J33: =IF('User Dashboard'!$C$10="TRC",J19,MAX(IF('User Dashboard'!$C$11="Base",J27,J28),J19)) -> 114 | K33: =IF('User Dashboard'!$C$10="TRC",K19,MAX(IF('User Dashboard'!$C$11="Base",K27,K28),K19)) -> 114 | ... AL33: =IF('User Dashboard'!$C$10="TRC",AL19,MAX(IF('User Dashboard'!$C$11="Base",AL27,AL28),AL19)) -> 114

Sheet T&D
B2: Gas Transportation Marginal Costs ($/therm, nominal)
B3: Transportation Marginal Costs
C4: Nominal $/Therm | D4: 2022 | E4: =D4+1 -> 2023 | F4: =E4+1 -> 2024 | G4: =F4+1 -> 2025 | H4: =G4+1 -> 2026 | I4: =H4+1 -> 2027 | J4: =I4+1 -> 2028 | K4: =J4+1 -> 2029 | L4: =K4+1 -> 2030 | ... AJ4: =AI4+1 -> 2054 | AL4: Key
B5: PG&E | C5: Residential | D5: 0.3825 | E5: 0.37003 | F5: 0.3825 | G5: =AVERAGE($D16:$F16)*(1+'User Dashboard'!$C$20)^('T&D'!G$4-2022) -> 0.39368042 | H5: =AVERAGE($D16:$F16)*(1+'User Dashboard'!$C$20)^('T&D'!H$4-2022) -> 0.40155403 | I5: =AVERAGE($D16:$F16)*(1+'User Dashboard'!$C$20)^('T&D'!I$4-2022) -> 0.40958511 | J5: =AVERAGE($D16:$F16)*(1+'User Dashboard'!$C$20)^('T&D'!J$4-2022) -> 0.41777682 | K5: =AVERAGE($D16:$F16)*(1+'User Dashboard'!$C$20)^('T&D'!K$4-2022) -> 0.42613235 | L5: =AVERAGE($D16:$F16)*(1+'User Dashboard'!$C$20)^('T&D'!L$4-2022) -> 0.434655 | M5: =AVERAGE($D16:$F16)*(1+'User Dashboard'!$C$20)^('T&D'!M$4-2022) -> 0.4433481 | N5: =AVERAGE($D16:$F16)*(1+'User Dashboard'!$C$20)^('T&D'!N$4-2022) -> 0.45221506 | ... AJ5: =AVERAGE($D16:$F16)*(1+'User Dashboard'!$C$20)^('T&D'!AJ$4-2022) -> 0.69911529 | AL5: =_xlfn.CONCAT($B$5,"-",C5) -> PG&E-Residential
C6: Commercial | D6: 0.23276 | E6: 0.236267 | F6: 0.20595 | G6: =AVERAGE($D17:$F17)*(1+'User Dashboard'!$C$20)^('T&D'!G$4-2022) -> 0.23429599 | H6: =AVERAGE($D17:$F17)*(1+'User Dashboard'!$C$20)^('T&D'!H$4-2022) -> 0.23898191 | I6: =AVERAGE($D17:$F17)*(1+'User Dashboard'!$C$20)^('T&D'!I$4-2022) -> 0.24376154 | J6: =AVERAGE($D17:$F17)*(1+'User Dashboard'!$C$20)^('T&D'!J$4-2022) -> 0.24863678 | K6: =AVERAGE($D17:$F17)*(1+'User Dashboard'!$C$20)^('T&D'!K$4-2022) -> 0.25360951 | L6: =AVERAGE($D17:$F17)*(1+'User Dashboard'!$C$20)^('T&D'!L$4-2022) -> 0.2586817 | M6: =AVERAGE($D17:$F17)*(1+'User Dashboard'!$C$20)^('T&D'!M$4-2022) -> 0.26385534 | N6: =AVERAGE($D17:$F17)*(1+'User Dashboard'!$C$20)^('T&D'!N$4-2022) -> 0.26913244 | ... AJ6: =AVERAGE($D17:$F17)*(1+'User Dashboard'!$C$20)^('T&D'!AJ$4-2022) -> 0.41607328 | AL6: =_xlfn.CONCAT($B$5,"-",C6) -> PG&E-Commercial
C7: Total Core | D7: 0.28163 | E7: 0.285878 | F7: 0.31218 | G7: =AVERAGE($D18:$F18)*(1+'User Dashboard'!$C$20)^('T&D'!G$4-2022) -> 0.30490636 | H7: =AVERAGE($D18:$F18)*(1+'User Dashboard'!$C$20)^('T&D'!H$4-2022) -> 0.31100449 | I7: =AVERAGE($D18:$F18)*(1+'User Dashboard'!$C$20)^('T&D'!I$4-2022) -> 0.31722458 | J7: =AVERAGE($D18:$F18)*(1+'User Dashboard'!$C$20)^('T&D'!J$4-2022) -> 0.32356907 | K7: =AVERAGE($D18:$F18)*(1+'User Dashboard'!$C$20)^('T&D'!K$4-2022) -> 0.33004045 | L7: =AVERAGE($D18:$F18)*(1+'User Dashboard'!$C$20)^('T&D'!L$4-2022) -> 0.33664126 | M7: =AVERAGE($D18:$F18)*(1+'User Dashboard'!$C$20)^('T&D'!M$4-2022) -> 0.34337408 | N7: =AVERAGE($D18:$F18)*(1+'User Dashboard'!$C$20)^('T&D'!N$4-2022) -> 0.35024157 | ... AJ7: =AVERAGE($D18:$F18)*(1+'User Dashboard'!$C$20)^('T&D'!AJ$4-2022) -> 0.54146634 | AL7: =_xlfn.CONCAT($B$5,"-",C7) -> PG&E-Total Core
B8: SoCal Gas | C8: Residential | D8: 0.23 | E8: 0.22 | F8: 0.22 | G8: =AVERAGE($D19:$F19)*(1+'User Dashboard'!$C$20)^('T&D'!G$4-2022) -> 0.23245528 | H8: =AVERAGE($D19:$F19)*(1+'User Dashboard'!$C$20)^('T&D'!H$4-2022) -> 0.23710439 | I8: =AVERAGE($D19:$F19)*(1+'User Dashboard'!$C$20)^('T&D'!I$4-2022) -> 0.24184647 | J8: =AVERAGE($D19:$F19)*(1+'User Dashboard'!$C$20)^('T&D'!J$4-2022) -> 0.2466834 | K8: =AVERAGE($D19:$F19)*(1+'User Dashboard'!$C$20)^('T&D'!K$4-2022) -> 0.25161707 | L8: =AVERAGE($D19:$F19)*(1+'User Dashboard'!$C$20)^('T&D'!L$4-2022) -> 0.25664941 | M8: =AVERAGE($D19:$F19)*(1+'User Dashboard'!$C$20)^('T&D'!M$4-2022) -> 0.2617824 | N8: =AVERAGE($D19:$F19)*(1+'User Dashboard'!$C$20)^('T&D'!N$4-2022) -> 0.26701805 | ... AJ8: =AVERAGE($D19:$F19)*(1+'User Dashboard'!$C$20)^('T&D'!AJ$4-2022) -> 0.41280447 | AL8: =_xlfn.CONCAT($B$8,"-",C8) -> SoCal Gas-Residential
C9: Commercial | D9: 0.13 | E9: 0.13 | F9: 0.13 | G9: =AVERAGE($D20:$F20)*(1+'User Dashboard'!$C$20)^('T&D'!G$4-2022) -> 0.13526968 | H9: =AVERAGE($D20:$F20)*(1+'User Dashboard'!$C$20)^('T&D'!H$4-2022) -> 0.13797507 | I9: =AVERAGE($D20:$F20)*(1+'User Dashboard'!$C$20)^('T&D'!I$4-2022) -> 0.14073458 | J9: =AVERAGE($D20:$F20)*(1+'User Dashboard'!$C$20)^('T&D'!J$4-2022) -> 0.14354927 | K9: =AVERAGE($D20:$F20)*(1+'User Dashboard'!$C$20)^('T&D'!K$4-2022) -> 0.14642025 | L9: =AVERAGE($D20:$F20)*(1+'User Dashboard'!$C$20)^('T&D'!L$4-2022) -> 0.14934866 | M9: =AVERAGE($D20:$F20)*(1+'User Dashboard'!$C$20)^('T&D'!M$4-2022) -> 0.15233563 | N9: =AVERAGE($D20:$F20)*(1+'User Dashboard'!$C$20)^('T&D'!N$4-2022) -> 0.15538234 | ... AJ9: =AVERAGE($D20:$F20)*(1+'User Dashboard'!$C$20)^('T&D'!AJ$4-2022) -> 0.24021794 | AL9: =_xlfn.CONCAT($B$8,"-",C9) -> SoCal Gas-Commercial
C10: Total Core | D10: 0.19 | E10: 0.19 | F10: 0.19 | G10: =AVERAGE($D21:$F21)*(1+'User Dashboard'!$C$20)^('T&D'!G$4-2022) -> 0.19770184 | H10: =AVERAGE($D21:$F21)*(1+'User Dashboard'!$C$20)^('T&D'!H$4-2022) -> 0.20165588 | I10: =AVERAGE($D21:$F21)*(1+'User Dashboard'!$C$20)^('T&D'!I$4-2022) -> 0.20568899 | J10: =AVERAGE($D21:$F21)*(1+'User Dashboard'!$C$20)^('T&D'!J$4-2022) -> 0.20980277 | K10: =AVERAGE($D21:$F21)*(1+'User Dashboard'!$C$20)^('T&D'!K$4-2022) -> 0.21399883 | L10: =AVERAGE($D21:$F21)*(1+'User Dashboard'!$C$20)^('T&D'!L$4-2022) -> 0.21827881 | M10: =AVERAGE($D21:$F21)*(1+'User Dashboard'!$C$20)^('T&D'!M$4-2022) -> 0.22264438 | N10: =AVERAGE($D21:$F21)*(1+'User Dashboard'!$C$20)^('T&D'!N$4-2022) -> 0.22709727 | ... AJ10: =AVERAGE($D21:$F21)*(1+'User Dashboard'!$C$20)^('T&D'!AJ$4-2022) -> 0.35108776 | AL10: =_xlfn.CONCAT($B$8,"-",C10) -> SoCal Gas-Total Core
B11: SDG&E | C11: Residential | D11: 0.33 | E11: 0.33 | F11: 0.33 | G11: =AVERAGE($D22:$F22)*(1+'User Dashboard'!$C$20)^('T&D'!G$4-2022) -> 0.34337688 | H11: =AVERAGE($D22:$F22)*(1+'User Dashboard'!$C$20)^('T&D'!H$4-2022) -> 0.35024442 | I11: =AVERAGE($D22:$F22)*(1+'User Dashboard'!$C$20)^('T&D'!I$4-2022) -> 0.35724931 | J11: =AVERAGE($D22:$F22)*(1+'User Dashboard'!$C$20)^('T&D'!J$4-2022) -> 0.36439429 | K11: =AVERAGE($D22:$F22)*(1+'User Dashboard'!$C$20)^('T&D'!K$4-2022) -> 0.37168218 | L11: =AVERAGE($D22:$F22)*(1+'User Dashboard'!$C$20)^('T&D'!L$4-2022) -> 0.37911582 | M11: =AVERAGE($D22:$F22)*(1+'User Dashboard'!$C$20)^('T&D'!M$4-2022) -> 0.38669814 | N11: =AVERAGE($D22:$F22)*(1+'User Dashboard'!$C$20)^('T&D'!N$4-2022) -> 0.3944321 | ... AJ11: =AVERAGE($D22:$F22)*(1+'User Dashboard'!$C$20)^('T&D'!AJ$4-2022) -> 0.60978401 | AL11: =_xlfn.CONCAT($B$11,"-",C11) -> SDG&E-Residential
C12: Commercial | D12: 0.2 | E12: 0.2 | F12: 0.2 | G12: =AVERAGE($D23:$F23)*(1+'User Dashboard'!$C$20)^('T&D'!G$4-2022) -> 0.2081072 | H12: =AVERAGE($D23:$F23)*(1+'User Dashboard'!$C$20)^('T&D'!H$4-2022) -> 0.21226934 | I12: =AVERAGE($D23:$F23)*(1+'User Dashboard'!$C$20)^('T&D'!I$4-2022) -> 0.21651473 | J12: =AVERAGE($D23:$F23)*(1+'User Dashboard'!$C$20)^('T&D'!J$4-2022) -> 0.22084503 | K12: =AVERAGE($D23:$F23)*(1+'User Dashboard'!$C$20)^('T&D'!K$4-2022) -> 0.22526193 | L12: =AVERAGE($D23:$F23)*(1+'User Dashboard'!$C$20)^('T&D'!L$4-2022) -> 0.22976716 | M12: =AVERAGE($D23:$F23)*(1+'User Dashboard'!$C$20)^('T&D'!M$4-2022) -> 0.23436251 | N12: =AVERAGE($D23:$F23)*(1+'User Dashboard'!$C$20)^('T&D'!N$4-2022) -> 0.23904976 | ... AJ12: =AVERAGE($D23:$F23)*(1+'User Dashboard'!$C$20)^('T&D'!AJ$4-2022) -> 0.36956607 | AL12: =_xlfn.CONCAT($B$11,"-",C12) -> SDG&E-Commercial
C13: Total Core | D13: 0.27 | E13: 0.27 | F13: 0.27 | G13: =AVERAGE($D24:$F24)*(1+'User Dashboard'!$C$20)^('T&D'!G$4-2022) -> 0.28094472 | H13: =AVERAGE($D24:$F24)*(1+'User Dashboard'!$C$20)^('T&D'!H$4-2022) -> 0.28656361 | I13: =AVERAGE($D24:$F24)*(1+'User Dashboard'!$C$20)^('T&D'!I$4-2022) -> 0.29229489 | J13: =AVERAGE($D24:$F24)*(1+'User Dashboard'!$C$20)^('T&D'!J$4-2022) -> 0.29814078 | K13: =AVERAGE($D24:$F24)*(1+'User Dashboard'!$C$20)^('T&D'!K$4-2022) -> 0.3041036 | L13: =AVERAGE($D24:$F24)*(1+'User Dashboard'!$C$20)^('T&D'!L$4-2022) -> 0.31018567 | M13: =AVERAGE($D24:$F24)*(1+'User Dashboard'!$C$20)^('T&D'!M$4-2022) -> 0.31638939 | N13: =AVERAGE($D24:$F24)*(1+'User Dashboard'!$C$20)^('T&D'!N$4-2022) -> 0.32271717 | ... AJ13: =AVERAGE($D24:$F24)*(1+'User Dashboard'!$C$20)^('T&D'!AJ$4-2022) -> 0.49891419 | AL13: =_xlfn.CONCAT($B$11,"-",C13) -> SDG&E-Total Core
C15: 2022$/Therm | D15: 2022 | E15: =D15+1 -> 2023 | F15: =E15+1 -> 2024
B16: PG&E | C16: Residential | D16: =D5/(1+'User Dashboard'!$C$20)^('T&D'!D$15-2022) -> 0.3825 | E16: =E5/(1+'User Dashboard'!$C$20)^('T&D'!E$15-2022) -> 0.36277451 | F16: =F5/(1+'User Dashboard'!$C$20)^('T&D'!F$15-2022) -> 0.36764706
C17: Commercial | D17: =D6/(1+'User Dashboard'!$C$20)^('T&D'!D$15-2022) -> 0.23276 | E17: =E6/(1+'User Dashboard'!$C$20)^('T&D'!E$15-2022) -> 0.23163431 | F17: =F6/(1+'User Dashboard'!$C$20)^('T&D'!F$15-2022) -> 0.19795271
C18: Total Core | D18: =D7/(1+'User Dashboard'!$C$20)^('T&D'!D$15-2022) -> 0.28163 | E18: =E7/(1+'User Dashboard'!$C$20)^('T&D'!E$15-2022) -> 0.28027255 | F18: =F7/(1+'User Dashboard'!$C$20)^('T&D'!F$15-2022) -> 0.30005767
B19: SoCal Gas | C19: Residential | D19: =D8/(1+'User Dashboard'!$C$20)^('T&D'!D$15-2022) -> 0.23 | E19: =E8/(1+'User Dashboard'!$C$20)^('T&D'!E$15-2022) -> 0.21568627 | F19: =F8/(1+'User Dashboard'!$C$20)^('T&D'!F$15-2022) -> 0.21145713
C20: Commercial | D20: =D9/(1+'User Dashboard'!$C$20)^('T&D'!D$15-2022) -> 0.13 | E20: =E9/(1+'User Dashboard'!$C$20)^('T&D'!E$15-2022) -> 0.12745098 | F20: =F9/(1+'User Dashboard'!$C$20)^('T&D'!F$15-2022) -> 0.12495194
C21: Total Core | D21: =D10/(1+'User Dashboard'!$C$20)^('T&D'!D$15-2022) -> 0.19 | E21: =E10/(1+'User Dashboard'!$C$20)^('T&D'!E$15-2022) -> 0.18627451 | F21: =F10/(1+'User Dashboard'!$C$20)^('T&D'!F$15-2022) -> 0.18262207
B22: SDG&E | C22: Residential | D22: =D11/(1+'User Dashboard'!$C$20)^('T&D'!D$15-2022) -> 0.33 | E22: =E11/(1+'User Dashboard'!$C$20)^('T&D'!E$15-2022) -> 0.32352941 | F22: =F11/(1+'User Dashboard'!$C$20)^('T&D'!F$15-2022) -> 0.3171857
C23: Commercial | D23: =D12/(1+'User Dashboard'!$C$20)^('T&D'!D$15-2022) -> 0.2 | E23: =E12/(1+'User Dashboard'!$C$20)^('T&D'!E$15-2022) -> 0.19607843 | F23: =F12/(1+'User Dashboard'!$C$20)^('T&D'!F$15-2022) -> 0.19223376
C24: Total Core | D24: =D13/(1+'User Dashboard'!$C$20)^('T&D'!D$15-2022) -> 0.27 | E24: =E13/(1+'User Dashboard'!$C$20)^('T&D'!E$15-2022) -> 0.26470588 | F24: =F13/(1+'User Dashboard'!$C$20)^('T&D'!F$15-2022) -> 0.25951557
B27: Gas Transportation Allocation
B28: Natural Gas Customer Shape
C29: PG&E | F29: Socal Gas | I29: SDG&E
C30: Residential | D30: Commercial | E30: Total Core | F30: Residential | G30: Commercial | H30: Total Core | I30: Residential | J30: Commercial | K30: Total Core
B31: January | C31: 0.162 | D31: 0.128 | E31: 0.151 | F31: 0.138 | G31: 0.105 | H31: 0.126 | I31: 0.136 | J31: 0.109 | K31: 0.123
B32: February | C32: 0.133 | D32: 0.113 | E32: 0.127 | F32: 0.121 | G32: 0.099 | H32: 0.112 | I32: 0.119 | J32: 0.102 | K32: 0.11
B33: March | C33: 0.098 | D33: 0.092 | E33: 0.096 | F33: 0.105 | G33: 0.092 | H33: 0.1 | I33: 0.109 | J33: 0.096 | K33: 0.102
B34: April | C34: 0.077 | D34: 0.081 | E34: 0.078 | F34: 0.087 | G34: 0.085 | H34: 0.086 | I34: 0.09 | J34: 0.088 | K34: 0.088
B35: May | C35: 0.056 | D35: 0.069 | E35: 0.061 | F35: 0.063 | G35: 0.074 | H35: 0.067 | I35: 0.067 | J35: 0.075 | K35: 0.071
B36: June | C36: 0.046 | D36: 0.061 | E36: 0.051 | F36: 0.049 | G36: 0.07 | H36: 0.057 | I36: 0.051 | J36: 0.068 | K36: 0.059
B37: July | C37: 0.041 | D37: 0.057 | E37: 0.046 | F37: 0.047 | G37: 0.068 | H37: 0.055 | I37: 0.049 | J37: 0.066 | K37: 0.057
B38: August | C38: 0.04 | D38: 0.059 | E38: 0.046 | F38: 0.047 | G38: 0.068 | H38: 0.055 | I38: 0.048 | J38: 0.065 | K38: 0.057
B39: September | C39: 0.043 | D39: 0.062 | E39: 0.049 | F39: 0.047 | G39: 0.069 | H39: 0.055 | I39: 0.047 | J39: 0.065 | K39: 0.056
B40: October | C40: 0.052 | D40: 0.068 | E40: 0.057 | F40: 0.058 | G40: 0.074 | H40: 0.064 | I40: 0.057 | J40: 0.069 | K40: 0.063
B41: November | C41: 0.098 | D41: 0.091 | E41: 0.096 | F41: 0.092 | G41: 0.088 | H41: 0.091 | I41: 0.089 | J41: 0.086 | K41: 0.088
B42: December | C42: 0.154 | D42: 0.119 | E42: 0.142 | F42: 0.145 | G42: 0.107 | H42: 0.132 | I42: 0.139 | J42: 0.11 | K42: 0.126
B45: Winter Throughput | C45: =SUM(C41:C42,C31:C33) -> 0.645 | D45: =SUM(D41:D42,D31:D33) -> 0.543 | E45: =SUM(E41:E42,E31:E33) -> 0.612 | F45: =SUM(F41:F42,F31:F33) -> 0.601 | G45: =SUM(G41:G42,G31:G33) -> 0.491 | H45: =SUM(H41:H42,H31:H33) -> 0.561 | I45: =SUM(I41:I42,I31:I33) -> 0.592 | J45: =SUM(J41:J42,J31:J33) -> 0.503 | K45: =SUM(K41:K42,K31:K33) -> 0.549
B46: Summer | C46: =1-C45 -> 0.355 | D46: =1-D45 -> 0.457 | E46: =1-E45 -> 0.388 | F46: =1-F45 -> 0.399 | G46: =1-G45 -> 0.509 | H46: =1-H45 -> 0.439 | I46: =1-I45 -> 0.408 | J46: =1-J45 -> 0.497 | K46: =1-K45 -> 0.451
...

Sheet Methane Leakage
B2: Methane leakage adders | C2: Selected Adder at Specified GWP time horizon | D2: Upstream - In-State | E2: Upstream - National Average
B3: Variable | D3: used in TRC | E3: used in SCT | F3: Note
B4: Upstream methane leakage adder | C4: =IF('User Dashboard'!$C$10="TRC",'Methane Leakage'!D4,'Methane Leakage'!E4)*$C$16/$C$14 -> 0.0557 | D4: =D5*$C$21 -> 0.0557 | E4: =E5*$C$21 -> 0.20985401 | F4: Methane leakage upstream of natural gas power plants. Also applies to programs that change natural gas consumption only. Methane leakage avoided cost is this percentage times the value of GHG emissions
B5: Upstream methane leakage rate | C5: =IF('User Dashboard'!$C$10="TRC",'Methane Leakage'!D5,'Methane Leakage'!E5) -> 0.00610472 | D5: 0.00610472 | E5: 0.023
B7: Residential behind-the-meter methane leakage adder | C7: =C8*C21 -> 0.037864964 | F7: Applies only to programs that eliminate natural gas appliances from a residential building.
B8: Residential behind-the-meter methane leakage rate | C8: 0.00415
B11: Active GWP time horizon | C11: 100-yr | D11: Choose from dropdown (100-yr default)
B13: Methane leakage GWPs (AR4)
B14: 100-yr | C14: 25
B15: 20-yr | C15: 72
B16: Active GWP | C16: =INDEX(C14:C15,MATCH(C11,B14:B15,0)) -> 25
B18: Methane leakage rate conversion
B19: Methane GWP if Leaked | C19: 25
B20: Difference in molar mass between CH4 and CO2 | C20: 2.74
B21: Methane leakage rate to adder conversion | C21: =C19/C20 -> 9.1240876

Sheet Other Inputs
B2: Compression Factor and Loss Input
C4: PG&E | D4: SoCal Gas | E4: SDG&E
B5: Compression Factor | C5: 0 | D5: 0.0039 | E5: 0.004
B6: Loss and Unaccounted | C6: 0.0241 | D6: 0.0137 | E6: 0.01
B7: * PG&E LUAF figure includes both LUAF and compression
B9: IRP Inputs
B11: Inflation | C11: 0.02
B12: PG&E | C12: 0 | D12: 0.0727
B13: SoCalGas | C13: 0 | D13: 0.071
B14: SDG&E | C14: 0 | D14: 0.0718
C16: TRC | D16: SCT
B17: Real Discount Rate | D17: 0.03
B18: Nominal Discount Rate | C18: =AVERAGE(C12:C14) -> 0 | D18: =(1+C11)*(1+D17)-1 -> 0.0506
B20: Unit Conversion
B22: Therms / MMBtu | C22: 10

Sheet AGIC
B2: Measure Inputs
B4: Program Year | C4: 2021
B5: Inflation Rate | C5: ='User Dashboard'!$C$20 -> 0.02
B7: Project Name | C7: Utility | D7: Subdivision/Development | E7: Building Type | F7: Avoided Mainline Extension (ft) | G7: Avoided Number of Services | H7: Avoided Number of Meters
B8: Example_Project_Name_PGE | C8: PG&E | D8: New Greenfield | E8: Residential Single Family | F8: 1 | G8: 1 | H8: 1
B9: Example_Project_Name_SCG | C9: Socal Gas | D9: New Greenfield | E9: Residential Single Family | F9: 1 | G9: 1 | H9: 1
B10: Example_Project_Name_SDGE | C10: SDG&E | D10: New Greenfield | E10: Residential Single Family | F10: 1 | G10: 1 | H10: 1
B20: Measure Results
B22: Project Name | C22: ="Total Avoided Mainline Extension Costs ($" &$C$4 & ")" -> Total Avoided Mainline Extension Costs ($2021) | D22: ="Total Avoided Service Extension Costs ($" &$C$4 & ")" -> Total Avoided Service Extension Costs ($2021) | E22: ="Total Avoided Meter Costs ($" &$C$4 & ")" -> Total Avoided Meter Costs ($2021) | F22: ="Total Avoided Gas Infrastructure Costs ($" &$C$4 & ")" -> Total Avoided Gas Infrastructure Costs ($2021) | G22: Input Dollar Year
B23: =IF(B8="", "", B8) -> Example_Project_Name_PGE | C23: {=IFERROR(INDEX($D$41:$F$44, MATCH(1, ($D8 = $B$41:$B$44)*($E8=$C$41:$C$44), 0), MATCH($C8, $D$40:$F$40, 0))*(1+$C$5)^($C$4-$G23), 0)*$F8} -> 21.42 | D23: =IFERROR(INDEX($D$49:$F$50, MATCH($D8, $B$49:$B$50, 0), MATCH($C8, $D$48:$F$48, 0)) *(1+$C$5)^($C$4-$G23), 0)*$G8 -> 848.64 | E23: {=IFERROR(INDEX($D$55:$F$62, MATCH(1, ($D8 = $B$55:$B$62)*($E8=$C$55:$C$62), 0), MATCH($C8, $D$54:$F$54, 0))*(1+$C$5)^($C$4-$G23), 0)*$H8} -> 588.54 | F23: =SUM($C23:$E23) -> 1458.6 | G23: =IFERROR(INDEX($D$37:$F$37, MATCH($C8, $D$40:$F$40, 0)), "") -> 2020
B24: =IF(B9="", "", B9) -> Example_Project_Name_SCG | C24: {=IFERROR(INDEX($D$41:$F$44, MATCH(1, ($D9 = $B$41:$B$44)*($E9=$C$41:$C$44), 0), MATCH($C9, $D$40:$F$40, 0))*(1+$C$5)^($C$4-$G24), 0)*$F9} -> 30.82 | D24: =IFERROR(INDEX($D$49:$F$50, MATCH($D9, $B$49:$B$50, 0), MATCH($C9, $D$48:$F$48, 0)) *(1+$C$5)^($C$4-$G24), 0)*$G9 -> 7620 | E24: {=IFERROR(INDEX($D$55:$F$62, MATCH(1, ($D9 = $B$55:$B$62)*($E9=$C$55:$C$62), 0), MATCH($C9, $D$54:$F$54, 0))*(1+$C$5)^($C$4-$G24), 0)*$H9} -> 489 | F24: =SUM($C24:$E24) -> 8139.82 | G24: =IFERROR(INDEX($D$37:$F$37, MATCH($C9, $D$40:$F$40, 0)), "") -> 2021
